tests/complex_76.in
40
o
18 B 100 ANET 1131 630
3 B 101 AMOV 1338 276
3 S 102 AU 678 94
16 B 103 AG 1768 737
19 B 104 ASGI 1777 150
35 B 105 AVA 321 529
3 S 106 BE 979 932
18 B 107 ACCO 458 576
6 S 108 BAC^M 1268 973
15 B 109 BEST 1820 885
29 S 110 ATEK 1514 362
35 S 111 BBAR 1010 803
31 S 112 AVB 1471 464
26 B 113 AXTA 649 696
39 S 114 BAC^L 1322 322
5 S 115 AFTR 1474 519
38 B 116 AORT 1566 617
24 S 117 AZUL 464 291
10 S 118 AEVA 702 918
9 B 119 BGH 1482 745
28 S 120 AUB 100 712
8 B 121 ARCO 276 426
24 S 122 BGSX 883 732
31 B 123 ACCO 1865 270
15 S 124 ARCH 1686 547
35 S 125 ASC 1047 582
23 B 126 AMWL 1971 538
33 B 127 AYX 545 197
37 S 128 ABT 1223 275
8 S 129 AGRO 1611 22
36 S 130 AIR 1533 878
2 S 131 ATR 1969 874
0 B 132 ALL^G 1666 209
6 B 133 APTV^A 869 467
16 S 134 ARGO 952 254
37 S 135 ABG 465 90
0 S 136 BC^B 1242 559
23 S 137 AMCR 751 49
3 B 138 AMN 821 443
33 B 139 BHIL 1294 243
39 B 140 AU 207 582
10 B 141 AMRC 1032 59
27 B 142 APCA 1375 843
39 S 143 BIP^B 430 882
13 S 144 BMEZ 651 773
28 B 145 AMC 1032 378
25 B 146 ATH^B 481 609
32 S 147 BAK 1786 919
4 S 148 AFTR 1799 995
30 B 149 ATH^E 1627 220
11 B 150 BB 1507 427
33 S 151 AWR 302 60
36 S 152 ATEK 1613 487
0 S 153 ADNT 870 387
24 S 154 BMEZ 1910 436
17 B 155 ARIS 1497 729
33 S 156 AWF 1215 52
12 B 157 AIU 685 74
24 S 158 BAC^K 1753 933
22 S 159 AMG 884 132
1 S 160 BLDR 1337 174
20 S 161 APGB 1658 964
33 B 162 ALL^H 758 453
9 S 163 AA 387 471
27 S 164 ACR^D 1117 112
26 B 165 ATCO 912 607
5 S 166 BAC^Q 1669 954
36 S 167 BGH 695 101
26 B 168 APRN 1475 224
21 B 169 ALE 1237 215
15 B 170 BBN 1433 396
14 S 171 BJ 1333 50
33 S 172 AGM^D 228 970
3 S 173 BANC 1343 664
0 S 174 ATI 1529 123
18 B 175 AIN 344 162
30 B 176 AWP 1916 449
2 B 177 BCE 1750 562
15 B 178 AGX 1876 513
15 S 179 AL^A 1676 316
28 S 180 AMN 331 625
1 B 181 AHL^C 1406 415
20 B 182 BC^A 1604 685
24 B 183 AYX 1295 439
5 B 184 AQN 728 252
10 S 185 AA 190 230
11 S 186 APH 650 198
32 B 187 ABT 261 156
37 B 188 BGX 578 53
14 B 189 APD 655 575
3 B 190 AYX 1847 498
0 S 191 AAIC^B 1285 567
27 S 192 ADC 1224 196
23 B 193 BEP 645 506
31 S 194 BDXB 1032 609
22 B 195 APD 1986 890
9 B 196 BEDU 1379 324
17 B 197 ARMK 1769 585
19 B 198 BCAT 1347 896
1 B 199 ADM 622 337
14 S 200 AES 692 668
0 B 201 BAC^P 1537 902
0 B 202 ALCC 1517 736
22 S 203 BCAT 1771 287
36 B 204 ALK 282 192
34 S 205 BJ 1133 845
35 S 206 AGAC 1453 998
0 B 207 ASR 314 345
26 B 208 BIT 170 576
37 S 209 BF/B 211 279
8 B 210 ATTO 420 531
17 S 211 AIR 1214 382
4 S 212 AMRX 783 73
32 B 213 ALLY 1106 56
31 S 214 ABEV 1336 365
37 B 215 ABR^D 1367 906
14 S 216 ABR^D 967 629
19 S 217 ADX 168 796
31 B 218 ATH^A 443 776
35 B 219 AAIN 1984 907
26 B 220 AFT 1825 555
15 B 221 AGAC 350 776
23 B 222 AGM^F 943 254
5 B 223 ALL^G 1472 522
13 S 224 AMAM 292 757
26 B 225 AME 1850 489
35 B 226 ABBV 251 418
17 B 227 AMRC 1257 240
15 B 228 BEN 1197 14
5 S 229 AMTD 452 268
3 S 230 AQNB 224 109
11 B 231 BIT 442 929
25 B 232 AGCO 308 878
5 B 233 AFB 1079 264
6 B 234 BGH 1957 392
4 B 235 BCH 1633 757
27 B 236 BAP 687 128
27 B 237 APG 1957 78
25 B 238 ARCH 1414 72
13 B 239 ACR^D 1974 396
9 S 240 ARL 1372 421
12 B 241 BIG 1349 977
31 S 242 AIT 1879 427
9 B 243 BMI 224 66
28 S 244 ACR^D 240 926
20 S 245 ACDI 885 267
16 S 246 AME 687 561
12 S 247 BAX 1427 909
33 S 248 AMWL 1637 763
3 B 249 AVK 316 613
29 B 250 BFAC 1214 417
31 B 251 AM 1869 626
4 B 252 AQN 1120 211
36 B 253 AMWL 1198 692
27 B 254 BFS^E 232 553
27 S 255 ALG 1737 380
29 S 256 BBDO 876 715
17 S 257 AWR 1771 217
38 B 258 BALL 1877 574
31 B 259 AHL^C 1677 224
3 B 260 ASGN 1741 500
0 S 261 AES 1007 858
20 S 262 AMH 957 271
19 B 263 BACA 657 820
22 B 264 ALLG 1925 622
16 B 265 AMBP 1041 144
5 B 266 AER 1109 522
12 S 267 BCS 897 810
16 B 268 AL^A 1781 677
22 B 269 AVY 1671 697
31 S 270 APTV^A 1626 931
29 S 271 BGB 1837 765
38 S 272 AAIC 1935 284
35 B 273 BAC^E 451 183
20 B 274 ANAC 1211 994
37 B 275 AI 1532 66
17 S 276 ALLG 1731 177
10 B 277 BIGZ 653 909
7 B 278 AP 1902 694
18 S 279 BKDT 1273 583
19 S 280 ASB 1345 11
23 B 281 AROC 1257 85
10 B 282 AVD 1712 93
25 B 283 BKT 219 109
29 S 284 AIU 1572 797
28 S 285 ACRE 1694 116
25 B 286 BIP 422 70
33 B 287 AA 1002 311
36 B 288 BC^B 1467 828
39 B 289 APCA 403 137
5 B 290 BFS^D 1704 101
21 S 291 ACA 1603 79
11 S 292 ASC 935 448
34 B 293 ASH 784 400
14 B 294 AXS 150 964
18 B 295 ARES 445 883
7 S 296 BHR^D 707 619
15 S 297 ALC 1029 222
4 B 298 BIPH 1217 165
7 S 299 BHIL 878 438
33 B 300 ANF 904 212
24 S 301 AZRE 1478 771
16 S 302 APGB 1443 832
36 B 303 BLK 1295 74
11 B 304 ASG 1299 148
1 S 305 AR 461 96
2 B 306 AJX 1373 382
34 B 307 AFGE 1088 619
2 B 308 ALSN 1949 340
36 S 309 BKD 399 157
34 S 310 AMBC 1262 337
33 B 311 BCS 424 655
35 S 312 AVA 1271 22
33 S 313 ASG 1478 980
25 S 314 AJG 1270 526
3 S 315 ARMK 1191 685
25 S 316 ATCO^D 774 163
17 B 317 ABB 1240 934
13 S 318 BKE 623 187
15 B 319 AGTI 1963 326
38 S 320 AFG 1014 259
32 B 321 BKE 951 63
23 S 322 BML^H 449 40
5 S 323 BHR 1837 582
22 S 324 AFGE 259 343
27 S 325 ALTG^A 1137 706
13 B 326 AFGC 1547 369
9 S 327 ATCO^H 183 373
23 S 328 BIG 1764 176
20 S 329 ALC 399 414
7 S 330 AGRO 1977 550
32 S 331 BKI 799 901
15 B 332 ABC 1015 79
28 S 333 BBW 723 375
24 S 334 BGS 363 653
9 S 335 AI 1962 659
20 B 336 ALSN 1287 638
10 S 337 AHL^E 1259 222
35 B 338 ADM 1482 616
10 B 339 ARL 1427 88
13 S 340 ACP^A 1433 663
9 B 341 BHV 1922 598
39 B 342 BBVA 1336 737
21 S 343 AGCO 158 238
14 S 344 BEP 837 930
18 B 345 AIV 388 295
3 B 346 AXL 1909 414
2 S 347 AEO 1443 394
35 B 348 ALL^I 1743 179
8 S 349 BHP 1118 338
6 S 350 ALC 534 587
21 S 351 BKDT 1820 139
14 B 352 BDC 1988 231
10 B 353 ALK 1185 626
33 B 354 BLK 697 405
39 B 355 BIP^A 1943 592
31 S 356 BIG 898 557
11 S 357 BCSF 1622 732
10 S 358 BLW 890 98
19 S 359 ATIP 457 861
30 S 360 AJG 1841 484
36 S 361 ALB 1009 869
28 S 362 AMRC 237 101
13 B 363 AXR 729 473
38 B 364 AMWL 397 746
20 B 365 AZRE 165 674
17 S 366 ATEK 1590 621
28 S 367 BBLN 1363 137
7 S 368 BLUA 401 967
21 B 369 APO 606 544
17 B 370 BKH 1003 966
26 S 371 AAM^A 806 300
12 B 372 AVNT 341 646
22 B 373 BARK 911 796
35 S 374 BLDR 182 742
14 B 375 AMBC 615 250
0 S 376 BIPI 734 163
0 B 377 ASB 1675 17
28 B 378 ATO 338 453
38 S 379 ATHM 176 15
14 S 380 AGS 210 55
8 B 381 ATH^A 756 753
36 B 382 ACHR 1881 126
33 S 383 ASR 1523 453
26 B 384 BCH 2000 525
17 S 385 ACP 1346 344
36 B 386 BKDT 1084 102
39 B 387 BCS 648 273
4 B 388 ACV 1125 115
22 S 389 BGSX 274 379
1 S 390 BCSF 524 72
2 S 391 BEDU 274 343
4 S 392 AL 333 984
22 B 393 AMC 111 426
32 B 394 BEPI 1083 298
11 S 395 AHH^A 535 443
12 S 396 AHT^F 858 452
32 S 397 AWR 871 114
15 B 398 AR 1529 840
6 S 399 APCA 1229 394
1 B 400 AVYA 1179 816
5 B 401 AEVA 558 322
21 S 402 BEPH 1644 324
8 S 403 AVTR 424 157
2 B 404 BLW 1393 250
20 B 405 AJX 786 713
1 S 406 AN 954 666
3 B 407 AI 1450 106
14 B 408 BH 1843 134
14 B 409 BEP^A 1687 807
17 S 410 BIP^B 1076 861
24 S 411 ABBV 422 73
28 B 412 ATCO^I 1228 623
12 B 413 BHIL 806 316
37 S 414 AP 178 611
31 B 415 BBAR 529 527
17 S 416 AMH^G 1174 220
17 B 417 BGT 544 944
34 B 418 ATIP 411 978
21 S 419 BIPI 552 417
7 S 420 BE 1527 278
20 S 421 BHLB 185 530
20 S 422 ANET 1166 586
26 B 423 BIGZ 747 10
25 S 424 BBLN 1897 649
10 B 425 BKSY 864 593
14 B 426 AMBC 1456 615
36 B 427 BILL 992 794
10 B 428 AKR 1223 444
3 B 429 AVA 919 928
14 B 430 BAC 799 898
21 S 431 BDJ 148 947
28 B 432 BLDR 757 417
37 B 433 ARI 1399 994
21 B 434 AGAC 1810 445
10 B 435 AWF 983 513
7 S 436 AUD 1032 31
1 S 437 AI 1517 114
26 B 438 ANAC 234 525
23 B 439 BBAR 1059 980
39 B 440 ALCC 1727 971
34 B 441 ALE 1039 677
18 B 442 BIPC 964 170
31 B 443 BIT 250 322
17 S 444 BMAC 605 626
21 B 445 BMA 1225 802
8 S 446 BC^C 563 754
34 S 447 BIPI 641 191
25 S 448 BGS 311 745
34 S 449 AEL 1512 721
3 B 450 AME 1493 84
23 B 451 BALY 763 496
2 B 452 AKR 1453 334
28 S 453 AIV 203 95
6 B 454 BAH 495 575
10 B 455 ADT 444 429
21 B 456 ARL 576 856
34 B 457 BFS^E 878 680
33 B 458 AFGB 1010 321
12 S 459 AROC 1667 953
24 S 460 BFLY 355 490
38 B 461 AZRE 317 848
12 S 462 BF/B 949 533
0 S 463 ADNT 737 238
39 B 464 ARNC 1529 914
28 B 465 ASA 1021 821
36 B 466 AZZ 1038 460
