tests/complex_77.in
40
o
32 S 101 BLD 1943 933
20 B 102 BBUC 1830 565
37 S 103 AHL^E 343 414
6 B 104 BCSF 1472 124
38 B 105 ATIP 1055 916
9 S 106 ARCH 763 758
22 B 107 BAC^L 226 819
25 B 108 BFK 1322 763
37 B 109 ANF 1198 761
15 B 110 BAP 1176 494
1 C 104
29 S 112 AN 1321 600
19 C 104
7 C 102
5 C 107
9 C 102
26 C 112
32 S 118 BML^J 1889 191
36 S 119 BHE 781 425
11 B 120 BEPI 1275 889
28 B 121 ASGN 983 610
30 S 122 AMT 1198 90
22 C 111
4 C 120
13 C 101
38 B 126 AEFC 959 377
23 C 110
18 C 112
38 B 129 ARC 1665 19
6 B 130 AZO 1767 699
35 S 131 AMG 938 663
20 S 132 BBY 259 290
1 C 129
30 S 134 AHH^A 951 462
22 C 126
9 C 108
36 C 134
7 S 138 AAM^A 1441 283
25 B 139 AXP 1795 967
35 S 140 BARK 1166 962
37 B 141 ASB^E 870 854
8 C 118
35 B 143 BLX 374 526
3 C 115
8 S 145 BGT 669 19
27 S 146 ARE 563 143
18 B 147 AAM^A 461 384
29 B 148 BCX 1522 968
23 S 149 BLX 209 281
38 C 107
20 B 151 BCC 124 693
17 B 152 ALIT 616 861
1 C 136
28 B 154 BALL 1287 681
13 B 155 AL 1226 288
0 B 156 AMH 210 199
38 C 134
3 C 114
32 S 159 AGAC 286 276
9 C 115
35 S 161 AXL 1079 117
0 C 139
29 S 163 ARR^C 864 544
20 S 164 AKR 664 968
10 C 107
2 C 149
34 B 167 AFGE 1720 316
39 S 168 BBVA 291 609
14 B 169 A 723 540
22 S 170 ARNC 339 796
12 B 171 APTV 1994 163
25 S 172 AIT 989 417
16 S 173 AOD 1876 678
5 C 158
37 C 134
28 S 176 AKO/A 528 358
29 C 144
28 S 178 BIPC 491 617
28 C 175
13 C 131
13 S 181 ALE 819 299
9 B 182 AQNU 388 866
29 B 183 BIGZ 1444 659
14 S 184 AXS 566 256
25 B 185 BKN 1095 349
12 C 159
28 C 150
8 B 188 AMK 778 855
6 S 189 AMWL 1715 444
39 S 190 AEL 581 274
27 B 191 BGT 1088 422
14 S 192 ASC 1112 665
7 B 193 ARCO 763 395
21 B 194 ASGI 1569 249
19 B 195 BCAT 1856 682
17 C 170
36 S 197 AVY 1443 947
29 B 198 AYI 1070 766
14 S 199 BMAC 954 467
11 S 200 AAIN 784 870
28 S 201 BCO 1840 969
32 C 132
16 B 203 AFG 582 234
20 S 204 BME 1573 196
11 B 205 AZRE 1892 530
4 B 206 BLUA 1790 780
10 S 207 AAIC^C 558 76
16 C 179
9 S 209 AMR 1041 35
14 C 177
10 S 211 ABEV 1949 490
2 S 212 AJG 1952 804
17 S 213 APD 1466 99
23 B 214 AGAC 788 686
10 S 215 BKE 680 991
14 S 216 BBU 139 495
5 S 217 AHT^I 1701 631
37 C 179
32 C 185
2 B 220 ANET 1541 115
32 S 221 AVK 145 691
35 S 222 BLD 185 313
18 S 223 AMG 261 733
34 S 224 BLDR 1307 817
11 B 225 AHT^I 103 210
4 C 207
23 B 227 ALSN 290 698
14 B 228 ABBV 1661 566
17 B 229 AORT 1028 437
26 B 230 BBN 713 779
15 C 192
37 B 232 ASB 1854 19
13 C 147
9 S 234 ADT 1126 303
23 S 235 AOD 549 23
16 C 147
24 S 237 AZUL 1326 516
8 S 238 AAIC^B 1550 930
1 S 239 AKA 1304 205
27 B 240 BEDU 1529 798
23 S 241 BDJ 1179 629
28 S 242 ARCO 1392 79
25 S 243 BEPC 1304 694
5 B 244 ACI 859 344
11 B 245 AAIC^C 1248 145
17 C 118
32 C 211
2 C 178
14 S 249 ATH^A 1298 62
8 B 250 BCSF 497 381
21 B 251 AVA 1229 530
33 C 242
35 B 253 BIPH 990 827
31 C 139
10 B 255 AZUL 750 281
9 S 256 BEPH 902 410
37 S 257 AKO/B 1709 664
3 C 243
23 B 259 BIPH 780 102
0 B 260 APE 1448 131
0 S 261 BAP 1866 576
9 B 262 AFL 480 90
36 B 263 AVK 1224 770
36 S 264 AHT^F 1786 15
0 B 265 BML^H 841 690
35 C 216
2 C 247
28 S 268 AMBP 485 907
33 S 269 BGT 258 258
29 B 270 ALL^I 860 87
26 S 271 AES 442 955
21 B 272 ABM 726 574
26 B 273 BAC^B 556 78
1 C 157
26 B 275 AKO/B 1224 402
30 S 276 AMPX 747 670
36 B 277 BMA 1798 13
14 C 222
33 B 279 BGSX 1310 912
19 C 222
7 C 253
38 B 282 ATKR 1749 435
37 S 283 ACI 975 57
36 S 284 ACA 1200 350
39 S 285 BFAM 1177 861
17 C 185
26 S 287 AGM^F 168 961
1 B 288 BAM 1564 527
19 C 254
39 S 290 ADX 1238 540
30 B 291 AIT 712 330
28 C 174
7 C 260
21 C 114
14 S 295 AEM 1869 392
24 C 224
26 B 297 AWK 884 867
24 B 298 AEFC 1308 759
5 S 299 AMRX 1860 552
30 C 120
34 B 301 ARW 874 160
29 B 302 AI 1697 589
8 C 227
3 C 193
17 C 287
19 B 306 ANAC 1267 754
19 S 307 AGAC 1321 565
26 S 308 AESC 382 16
37 B 309 AYX 1197 578
37 B 310 AZO 607 623
5 C 249
16 C 193
30 B 313 ASA 1296 723
37 S 314 ALIT 1945 555
6 B 315 BCSF 1737 363
16 C 241
0 C 298
31 C 305
10 B 319 AM 1095 802
11 S 320 ABR^D 538 250
3 B 321 ACDI 1632 51
37 C 131
20 B 323 ATCO 601 708
28 S 324 AVK 1383 832
35 B 325 ACRE 1914 276
10 C 268
17 S 327 AMCR 948 798
39 C 105
15 S 329 AA 253 86
22 C 191
31 C 105
24 C 251
7 C 106
23 C 215
24 B 335 AGI 1707 638
5 B 336 ATO 245 892
23 C 118
17 C 335
29 B 339 BFS^E 327 797
17 C 251
32 S 341 ASR 1489 653
11 C 126
8 S 343 AMX 666 886
36 C 244
19 B 345 AHT 1815 700
25 B 346 AEL^A 370 376
17 C 170
21 S 348 BFZ 1994 958
7 C 123
20 B 350 AGI 1829 297
0 S 351 BCSF 1487 876
28 B 352 BLDR 1167 871
15 S 353 ASA 597 447
21 C 181
23 S 355 BEP 1260 30
37 C 300
34 C 292
0 B 358 BCS 810 489
22 S 359 ATAQ 544 289
28 B 360 BMEZ 654 504
33 B 361 APO 200 983
35 B 362 AVK 794 716
9 B 363 ATI 778 233
17 B 364 ATI 961 467
31 B 365 AGRO 391 606
35 S 366 ATTO 442 523
34 B 367 A 1232 447
32 B 368 AMPX 1671 828
39 S 369 ASX 1891 925
27 B 370 AL 1406 820
14 C 284
7 C 121
39 S 373 BBD 1034 260
5 C 294
17 S 375 AIF 1405 612
35 S 376 AQNU 912 603
10 B 377 AHT^G 667 179
34 S 378 APAM 1713 557
2 B 379 AORT 851 892
11 S 380 AR 149 269
30 B 381 BIT 1852 794
8 C 253
20 B 383 BGT 846 375
3 S 384 BME 1367 344
1 B 385 ALCC 380 28
14 S 386 BHG 1976 110
12 S 387 APG 1010 746
26 S 388 AUB 1486 110
30 B 389 AB 1533 153
31 B 390 BHG 760 708
6 S 391 AOS 138 541
39 S 392 AKO/B 1903 725
7 C 162
15 C 231
8 C 226
10 C 316
38 S 397 AGO 806 341
32 S 398 AVD 1621 237
20 B 399 BAC^E 1959 650
14 C 302
28 S 401 BLUA 140 473
11 B 402 AVYA 900 355
20 B 403 AUY 1847 827
5 B 404 AHT^H 264 242
28 B 405 BAX 1318 385
16 S 406 ASH 253 823
21 S 407 ALEX 536 75
15 S 408 AGM^E 652 93
10 S 409 BEPH 568 368
27 S 410 BDX 1706 737
20 B 411 BML^J 1548 104
8 B 412 BAC^E 1230 51
17 C 249
18 S 414 BEP^A 1289 411
32 S 415 AXTA 1784 356
17 S 416 AKA 436 145
28 S 417 ACN 884 618
35 B 418 AGO 875 315
9 S 419 ACR^C 1278 94
11 S 420 AMP 1471 704
35 B 421 BAP 566 730
39 C 329
32 B 423 BEPI 1822 218
29 B 424 BAM 824 148
19 S 425 AOMR 626 897
31 C 406
7 B 427 AP 1361 177
5 C 414
9 S 429 AB 2000 551
24 B 430 ACRE 1982 333
9 C 374
0 B 432 ALE 413 926
25 S 433 AXL 664 941
9 S 434 AMH^H 474 879
30 C 419
24 S 436 AMG 1851 846
25 B 437 BLW 322 237
24 C 129
23 S 439 ABR 638 176
35 B 440 ACHR 711 246
32 S 441 AMC 360 991
38 S 442 BMA 737 617
18 S 443 AQNA 1204 841
17 B 444 BMEZ 556 571
37 B 445 BEPC 357 316
32 B 446 APG 176 857
11 B 447 AFGB 261 842
31 S 448 ABT 331 745
14 C 273
15 S 450 BDC 416 978
8 C 303
27 B 452 AME 992 65
19 B 453 AIV 1211 663
33 C 106
18 C 166
28 B 456 ACA 1293 936
27 C 160
8 C 437
11 S 459 AGL 1871 538
29 S 460 AGTI 916 393
23 B 461 BALL 264 910
27 C 361
29 S 463 ACP 932 635
11 S 464 ASPN 1668 426
16 S 465 BHK 1837 632
8 S 466 BML^J 898 274
34 S 467 AWP 1795 857
23 B 468 APD 1977 902
29 B 469 AIRC 906 293
12 B 470 BEST 566 873
13 B 471 ALX 1737 38
3 B 472 BE 794 688
28 S 473 AAIN 1535 498
17 C 414
28 C 247
8 B 476 BACA 1741 941
13 C 448
13 C 198
32 S 479 AXAC 200 361
6 C 247
31 C 197
34 S 482 AMRC 989 154
30 C 395
17 C 201
36 B 485 BIPI 930 825
14 B 486 AFGD 1068 860
38 B 487 BEPH 1105 524
11 B 488 AWR 293 628
22 C 139
20 S 490 ACHR 1209 42
29 S 491 BFH 766 491
26 B 492 ATR 1854 531
0 S 493 ARC 1280 415
34 C 243
33 S 495 APH 305 913
18 B 496 AMAM 984 301
12 S 497 ACEL 298 30
8 C 449
30 C 142
0 B 500 BFH 1923 637
24 S 501 AX 1173 745
39 C 112
36 C 380
23 C 471
39 S 505 ABR 1821 649
34 B 506 BHR 416 646
17 C 348
38 C 250
2 B 509 AHH 372 347
2 C 132
31 B 511 BFK 1154 966
11 S 512 BFH 1363 820
2 B 513 BIP^A 904 241
22 C 147
2 B 515 ARNC 697 945
1 C 202
28 B 517 AQUA 1006 133
10 B 518 AAIN 353 697
10 C 116
31 B 520 AESC 1726 202
12 B 521 BH 232 458
28 C 113
34 S 523 BCAT 1368 360
35 C 174
17 B 525 ATO 1117 630
24 B 526 ATCO^H 698 657
21 S 527 ARC 1306 196
29 B 528 BAC^P 1894 774
20 S 529 BEPH 1909 111
34 B 530 B 1497 135
3 B 531 BIP^B 533 936
25 B 532 ATH^E 370 717
18 S 533 BEPH 1138 91
38 C 248
25 B 535 AROC 1291 641
36 S 536 AUY 1954 55
6 B 537 ATIP 327 68
27 C 437
0 C 252
7 C 255
16 B 541 ADCT 342 924
30 C 332
9 C 317
10 C 539
24 S 545 ARR^C 687 366
19 S 546 BEP 1537 126
5 S 547 ARLO 1649 358
37 B 548 ADC^A 242 919
6 C 426
3 B 550 ARMK 967 743
5 S 551 AESC 675 766
29 C 250
13 B 553 AGM^G 904 995
